<mujoco model="openarm">
  <compiler angle="radian" meshdir="./meshes/" />

  <asset>
    <mesh name="body_link0" content_type="model/stl" file="body_link0.stl" scale="0.001 0.001 0.001"/>
    <mesh name="body_link0_symp" content_type="model/stl" file="body_link0_symp.stl" scale="0.001 0.001 0.001"/>
    <mesh name="link0" content_type="model/stl" file="link0.stl" scale="0.001 -0.001 0.001"/>
    <mesh name="link0_symp" content_type="model/stl" file="link0_symp.stl" scale="0.001 -0.001 0.001"/>
    <mesh name="link1" content_type="model/stl" file="link1.stl" scale="0.001 -0.001 0.001"/>
    <mesh name="link1_symp" content_type="model/stl" file="link1_symp.stl" scale="0.001 -0.001 0.001"/>
    <mesh name="link2" content_type="model/stl" file="link2.stl" scale="0.001 -0.001 0.001"/>
    <mesh name="link2_symp" content_type="model/stl" file="link2_symp.stl" scale="0.001 -0.001 0.001"/>
    <mesh name="link3" content_type="model/stl" file="link3.stl" scale="0.001 -0.001 0.001"/>
    <mesh name="link3_symp" content_type="model/stl" file="link3_symp.stl" scale="0.001 -0.001 0.001"/>
    <mesh name="link4" content_type="model/stl" file="link4.stl" scale="0.001 0.001 0.001"/>
    <mesh name="link4_symp" content_type="model/stl" file="link4_symp.stl" scale="0.001 0.001 0.001"/>
    <mesh name="link5" content_type="model/stl" file="link5.stl" scale="0.001 -0.001 0.001"/>
    <mesh name="link5_symp" content_type="model/stl" file="link5_symp.stl" scale="0.001 -0.001 0.001"/>
    <mesh name="link6" content_type="model/stl" file="link6.stl" scale="0.001 -0.001 0.001"/>
    <mesh name="link6_symp" content_type="model/stl" file="link6_symp.stl" scale="0.001 -0.001 0.001"/>
    <mesh name="link7" content_type="model/stl" file="link7.stl" scale="0.001 -0.001 0.001"/>
    <mesh name="link7_symp" content_type="model/stl" file="link7_symp.stl" scale="0.001 -0.001 0.001"/>
    <mesh name="link01" content_type="model/stl" file="link0.stl" scale="0.001 0.001 0.001"/>
    <mesh name="link0_symp1" content_type="model/stl" file="link0_symp.stl" scale="0.001 0.001 0.001"/>
    <mesh name="link11" content_type="model/stl" file="link1.stl" scale="0.001 0.001 0.001"/>
    <mesh name="link1_symp1" content_type="model/stl" file="link1_symp.stl" scale="0.001 0.001 0.001"/>
    <mesh name="link21" content_type="model/stl" file="link2.stl" scale="0.001 0.001 0.001"/>
    <mesh name="link2_symp1" content_type="model/stl" file="link2_symp.stl" scale="0.001 0.001 0.001"/>
    <mesh name="link31" content_type="model/stl" file="link3.stl" scale="0.001 0.001 0.001"/>
    <mesh name="link3_symp1" content_type="model/stl" file="link3_symp.stl" scale="0.001 0.001 0.001"/>
    <mesh name="link51" content_type="model/stl" file="link5.stl" scale="0.001 0.001 0.001"/>
    <mesh name="link5_symp1" content_type="model/stl" file="link5_symp.stl" scale="0.001 0.001 0.001"/>
    <mesh name="link61" content_type="model/stl" file="link6.stl" scale="0.001 0.001 0.001"/>
    <mesh name="link6_symp1" content_type="model/stl" file="link6_symp.stl" scale="0.001 0.001 0.001"/>
    <mesh name="link71" content_type="model/stl" file="link7.stl" scale="0.001 0.001 0.001"/>
    <mesh name="link7_symp1" content_type="model/stl" file="link7_symp.stl" scale="0.001 0.001 0.001"/>
    <mesh name="hand" content_type="model/stl" file="hand.stl" scale="0.001 0.001 0.001"/>
    <mesh name="finger" content_type="model/stl" file="finger.stl" scale="0.001 0.001 0.001"/>
    <mesh name="finger1" content_type="model/stl" file="finger.stl" scale="0.001 -0.001 0.001"/>

    <texture name="grid" type="2d" builtin="checker" width="512" height="512" rgb1=".1 .2 .3" rgb2=".2 .3 .4"/>
    <material name="grid" texture="grid" texrepeat="1 1" texuniform="true" reflectance=".2"/>
  </asset>

  <worldbody>
    <geom name="floor" size="0 0 .05" type="plane" material="grid" condim="3"/>
    <light name="spotlight" mode="targetbodycom" target="openarm_left_link1" diffuse=".8 .8 .8" specular="0.3 0.3 0.3" pos="0 -6 4" cutoff="30"/>
    <light name="top" pos="0 0 2" mode="trackcom"/>

    <geom name="openarm_body_link0_visual" type="mesh" contype="0" conaffinity="0" group="1" density="0" mesh="body_link0"/>
    <geom name="openarm_body_link0_collision" type="mesh" mesh="body_link0_symp"/>
    <geom name="openarm_left_link0_visual" pos="0 0.031 0.698" quat="0.707105 -0.707108 0 0" type="mesh" contype="0" conaffinity="0" group="1" density="0" mesh="link0"/>
    <geom name="openarm_left_link0_collision" pos="0 0.031 0.698" quat="0.707105 -0.707108 0 0" type="mesh" mesh="link0_symp"/>
    <geom name="openarm_right_link0_visual" pos="0 -0.031 0.698" quat="0.707105 0.707108 0 0" type="mesh" contype="0" conaffinity="0" group="1" density="0" mesh="link01"/>
    <geom name="openarm_right_link0_collision" pos="0 -0.031 0.698" quat="0.707105 0.707108 0 0" type="mesh" mesh="link0_symp1"/>
    <body name="openarm_left_link1" pos="0 0.0935 0.698" quat="0.707105 -0.707108 0 0">
      <inertial pos="0.00114677 -3.31999e-05 0.0539528" quat="0.999653 0.00178277 0.0262159 -0.0018256" mass="1.14167" diaginertia="0.00156853 0.001273 0.00101447"/>
      <joint name="openarm_left_joint1" pos="0 0 0" axis="0 0 1" range="-3.49066 1.39626" actuatorfrcrange="-40 40"/>
      <geom name="openarm_left_link1_visual" pos="0 0 -0.0625" quat="1 0 0 0" type="mesh" contype="0" conaffinity="0" group="1" density="0" mesh="link1"/>
      <geom name="openarm_left_link1_collision" pos="0 0 -0.0625" type="mesh" mesh="link1_symp"/>
      <body name="openarm_left_link2" pos="-0.0301 0 0.06" quat="0.707107 -0.707107 0 0">
        <inertial pos="0.00839629 2.01451e-08 0.0325665" quat="0.966167 0.00423301 0.257864 0.00305037" mass="0.277509" diaginertia="0.000421651 0.000376006 0.000169343"/>
        <joint name="openarm_left_joint2" pos="0 0 0" axis="-1 0 0" range="-3.31613 0.174533" actuatorfrcrange="-40 40"/>
        <geom name="openarm_left_link2_visual" pos="0.0301 0 -0.1225" type="mesh" contype="0" conaffinity="0" group="1" density="0" mesh="link2"/>
        <geom name="openarm_left_link2_collision" pos="0.0301 0 -0.1225" type="mesh" mesh="link2_symp"/>
        <body name="openarm_left_link3" pos="0.0301 0 0.06625">
          <inertial pos="-0.00210475 -0.000554909 0.0904747" quat="0.999951 -0.00493243 -0.00144148 0.00846755" mass="1.07386" diaginertia="0.00437205 0.00431934 0.000660613"/>
          <joint name="openarm_left_joint3" pos="0 0 0" axis="0 0 1" range="-1.5708 1.5708" actuatorfrcrange="-27 27"/>
          <geom name="openarm_left_link3_visual" pos="0 0 -0.18875" quat="1 0 0 0" type="mesh" contype="0" conaffinity="0" group="1" density="0" mesh="link3"/>
          <geom name="openarm_left_link3_collision" pos="0 0 -0.18875" quat="1 0 0 0" type="mesh" mesh="link3_symp"/>
          <body name="openarm_left_link4" pos="0 0.0315 0.15375">
            <inertial pos="-0.00290068 -0.0303058 0.0633964" quat="0.994282 0.0996876 0.0329726 -0.0194356" mass="0.634853" diaginertia="0.000624355 0.000518596 0.000325049"/>
            <joint name="openarm_left_joint4" pos="0 0 0" axis="0 1 0" range="0 2.44346" actuatorfrcrange="-27 27"/>
            <geom name="openarm_left_link4_visual" pos="0 -0.0315 -0.3425" quat="1 0 0 0" type="mesh" contype="0" conaffinity="0" group="1" density="0" mesh="link4"/>
            <geom name="openarm_left_link4_collision" pos="0 -0.0315 -0.3425" type="mesh" mesh="link4_symp"/>
            <body name="openarm_left_link5" pos="0 -0.0315 0.0955">
              <inertial pos="-0.00304967 -0.00088669 0.0430798" quat="0.583368 -0.0362076 0.0020034 0.811398" mass="0.615659" diaginertia="0.000448064 0.000420549 0.000323387"/>
              <joint name="openarm_left_joint5" pos="0 0 0" axis="0 0 1" range="-1.5708 1.5708" actuatorfrcrange="-7 7"/>
              <geom name="openarm_left_link5_visual" pos="0 0 -0.438" quat="1 0 0 0" type="mesh" contype="0" conaffinity="0" group="1" density="0" mesh="link5"/>
              <geom name="openarm_left_link5_collision" pos="0 0 -0.438" quat="1 0 0 0" type="mesh" mesh="link5_symp"/>
              <body name="openarm_left_link6" pos="0.0375 0 0.1205">
                <inertial pos="-0.0371366 -0.000332305 -9.49837e-05" quat="0.162305 0.716462 0.124543 0.666955" mass="0.475203" diaginertia="0.000159518 0.000156606 0.000142875"/>
                <joint name="openarm_left_joint6" pos="0 0 0" axis="1 0 0" range="-0.785398 0.785398" actuatorfrcrange="-7 7"/>
                <geom name="openarm_left_link6_visual" pos="-0.0375 0 -0.5585" quat="1 0 0 0" type="mesh" contype="0" conaffinity="0" group="1" density="0" mesh="link6"/>
                <geom name="openarm_left_link6_collision" pos="-0.0375 0 -0.5585" quat="1 0 0 0" type="mesh" mesh="link6_symp"/>
                <body name="openarm_left_link7" pos="-0.0375 0 0">
                  <inertial pos="0.000225407 -0.0493083 0.0527505" quat="0.562309 0.826922 -0.00037379 0.00302762" mass="0.815977" diaginertia="0.00265078 0.00228138 0.000591786"/>
                  <joint name="openarm_left_joint7" pos="0 0 0" axis="0 -1 0" range="-1.5708 1.5708" actuatorfrcrange="-7 7"/>
                  <geom name="openarm_left_link7_visual" pos="0 0 -0.5585" quat="1 0 0 0" type="mesh" contype="0" conaffinity="0" group="1" density="0" mesh="link7"/>
                  <geom name="openarm_left_link7_collision" pos="0 0 -0.5585" type="mesh" mesh="link7_symp"/>
                  <geom name="openarm_left_hand_visual" pos="0 0 -0.5584" quat="1 0 0 0" type="mesh" contype="0" conaffinity="0" group="1" density="0" mesh="hand"/>
                  <geom name="openarm_left_hand_collision" pos="0 0 -0.5584" quat="1 0 0 0" type="mesh" mesh="hand"/>
                  <body name="openarm_left_right_finger" pos="0 -0.006 0.1151">
                    <inertial pos="0.0064528 -0.01702 0.0219685" quat="0.904408 0.0781531 -0.188678 0.374618" mass="0.0360255" diaginertia="1.83333e-06 1.83333e-06 1.83333e-06"/>
                    <joint name="openarm_left_finger_joint1" pos="0 0 0" axis="0 -1 0" type="slide" range="0 0.044" actuatorfrcrange="-333 333"/>
                    <geom name="openarm_left_right_finger_visual" pos="0 0.05 -0.673001" quat="1 0 0 0" type="mesh" contype="0" conaffinity="0" group="1" density="0" mesh="finger1"/>
                    <geom name="openarm_left_right_finger_collision" pos="0 0.05 -0.673001" quat="1 0 0 0" type="mesh" mesh="finger"/>
                  </body>
                  <body name="openarm_left_left_finger" pos="0 0.006 0.1151">
                    <inertial pos="0.0064528 0.01702 0.0219685" quat="0.904408 0.0781531 -0.188678 0.374618" mass="0.0360255" diaginertia="1.83333e-06 1.83333e-06 1.83333e-06"/>
                    <joint name="openarm_left_finger_joint2" pos="0 0 0" axis="0 1 0" type="slide" range="0 0.044" actuatorfrcrange="-333 333"/>
                    <geom name="openarm_left_left_finger_visual" pos="0 -0.05 -0.673001" quat="1 0 0 0" type="mesh" contype="0" conaffinity="0" group="1" density="0" mesh="finger"/>
                    <geom name="openarm_left_left_finger_collision" pos="0 -0.05 -0.673001" quat="1 0 0 0" type="mesh" mesh="finger"/>
                  </body>
                </body>
              </body>
            </body>
          </body>
        </body>
      </body>
    </body>
    <body name="openarm_right_link1" pos="0 -0.0935 0.698" quat="0.707105 0.707108 0 0">
      <inertial pos="0.00114677 3.31999e-05 0.0539528" quat="0.999653 0.00178277 0.0262159 -0.0018256" mass="1.14167" diaginertia="0.00156853 0.001273 0.00101447"/>
      <joint name="openarm_right_joint1" pos="0 0 0" axis="0 0 1" range="-1.39626 3.49066" actuatorfrcrange="-40 40"/>
      <geom name="openarm_right_link1_visual" pos="0 0 -0.0625" quat="1 0 0 0" type="mesh" contype="0" conaffinity="0" group="1" density="0" mesh="link11"/>
      <geom name="openarm_right_link1_collision" pos="0 0 -0.0625" type="mesh" mesh="link1_symp1"/>
      <body name="openarm_right_link2" pos="-0.0301 0 0.06" quat="0.707107 0.707107 0 0">
        <inertial pos="0.00839629 -2.01451e-08 0.0325665" quat="0.966167 0.00423301 0.257864 0.00305037" mass="0.277509" diaginertia="0.000421651 0.000376006 0.000169343"/>
        <joint name="openarm_right_joint2" pos="0 0 0" axis="-1 0 0" range="-0.174533 3.31613" actuatorfrcrange="-40 40"/>
        <geom name="openarm_right_link2_visual" pos="0.0301 0 -0.1225" type="mesh" contype="0" conaffinity="0" group="1" density="0" mesh="link21"/>
        <geom name="openarm_right_link2_collision" pos="0.0301 0 -0.1225" quat="1 0 0 0" type="mesh" mesh="link2_symp1"/>
        <body name="openarm_right_link3" pos="0.0301 0 0.06625">
          <inertial pos="-0.00210475 0.000554909 0.0904747" quat="0.999951 -0.00493243 -0.00144148 0.00846755" mass="1.07386" diaginertia="0.00437205 0.00431934 0.000660613"/>
          <joint name="openarm_right_joint3" pos="0 0 0" axis="0 0 1" range="-1.5708 1.5708" actuatorfrcrange="-27 27"/>
          <geom name="openarm_right_link3_visual" pos="0 0 -0.18875" quat="1 0 0 0" type="mesh" contype="0" conaffinity="0" group="1" density="0" mesh="link31"/>
          <geom name="openarm_right_link3_collision" pos="0 0 -0.18875" quat="1 0 0 0" type="mesh" mesh="link3_symp1"/>
          <body name="openarm_right_link4" pos="0 0.0315 0.15375">
            <inertial pos="-0.00290068 -0.0303058 0.0633964" quat="0.994282 0.0996876 0.0329726 -0.0194356" mass="0.634853" diaginertia="0.000624355 0.000518596 0.000325049"/>
            <joint name="openarm_right_joint4" pos="0 0 0" axis="0 1 0" range="0 2.44346" actuatorfrcrange="-27 27"/>
            <geom name="openarm_right_link4_visual" pos="0 -0.0315 -0.3425" quat="1 0 0 0" type="mesh" contype="0" conaffinity="0" group="1" density="0" mesh="link4"/>
            <geom name="openarm_right_link4_collision" pos="0 -0.0315 -0.3425" type="mesh" mesh="link4_symp"/>
            <body name="openarm_right_link5" pos="0 -0.0315 0.0955">
              <inertial pos="-0.00304967 0.00088669 0.0430798" quat="0.583368 -0.0362076 0.0020034 0.811398" mass="0.615659" diaginertia="0.000448064 0.000420549 0.000323387"/>
              <joint name="openarm_right_joint5" pos="0 0 0" axis="0 0 1" range="-1.5708 1.5708" actuatorfrcrange="-7 7"/>
              <geom name="openarm_right_link5_visual" pos="0 0 -0.438" quat="1 0 0 0" type="mesh" contype="0" conaffinity="0" group="1" density="0" mesh="link51"/>
              <geom name="openarm_right_link5_collision" pos="0 0 -0.438" quat="1 0 0 0" type="mesh" mesh="link5_symp1"/>
              <body name="openarm_right_link6" pos="0.0375 0 0.1205">
                <inertial pos="-0.0371366 0.000332305 -9.49837e-05" quat="0.162305 0.716462 0.124543 0.666955" mass="0.475203" diaginertia="0.000159518 0.000156606 0.000142875"/>
                <joint name="openarm_right_joint6" pos="0 0 0" axis="1 0 0" range="-0.785398 0.785398" actuatorfrcrange="-7 7"/>
                <geom name="openarm_right_link6_visual" pos="-0.0375 0 -0.5585" quat="1 0 0 0" type="mesh" contype="0" conaffinity="0" group="1" density="0" mesh="link61"/>
                <geom name="openarm_right_link6_collision" pos="-0.0375 0 -0.5585" quat="1 0 0 0" type="mesh" mesh="link6_symp1"/>
                <body name="openarm_right_link7" pos="-0.0375 0 0">
                  <inertial pos="0.000225407 -0.0348469 0.0527505" quat="0.591772 0.8061 -0.00076286 0.00279989" mass="0.815977" diaginertia="0.00364382 0.00328963 0.000576585"/>
                  <joint name="openarm_right_joint7" pos="0 0 0" axis="0 1 0" range="-1.5708 1.5708" actuatorfrcrange="-7 7"/>
                  <geom name="openarm_right_link7_visual" pos="0 0 -0.5585" quat="1 0 0 0" type="mesh" contype="0" conaffinity="0" group="1" density="0" mesh="link71"/>
                  <geom name="openarm_right_link7_collision" pos="0 0 -0.5585" type="mesh" mesh="link7_symp1"/>
                  <geom name="openarm_right_hand_visual" pos="0 0 -0.5584" quat="1 0 0 0" type="mesh" contype="0" conaffinity="0" group="1" density="0" mesh="hand"/>
                  <geom name="openarm_right_hand_collision" pos="0 0 -0.5584" quat="1 0 0 0" type="mesh" mesh="hand"/>
                  <body name="openarm_right_right_finger" pos="0 -0.006 0.1151">
                    <inertial pos="0.0064528 -0.01702 0.0219685" quat="0.904408 0.0781531 -0.188678 0.374618" mass="0.0360255" diaginertia="1.83333e-06 1.83333e-06 1.83333e-06"/>
                    <joint name="openarm_right_finger_joint1" pos="0 0 0" axis="0 -1 0" type="slide" range="0 0.044" actuatorfrcrange="-333 333"/>
                    <geom name="openarm_right_right_finger_visual" pos="0 0.05 -0.673001" quat="1 0 0 0" type="mesh" contype="0" conaffinity="0" group="1" density="0" mesh="finger"/>
                    <geom name="openarm_right_right_finger_collision" pos="0 0.05 -0.673001" quat="1 0 0 0" type="mesh" mesh="finger"/>
                  </body>
                  <body name="openarm_right_left_finger" pos="0 0.006 0.1151">
                    <inertial pos="0.0064528 0.01702 0.0219685" quat="0.904408 0.0781531 -0.188678 0.374618" mass="0.0360255" diaginertia="1.83333e-06 1.83333e-06 1.83333e-06"/>
                    <joint name="openarm_right_finger_joint2" pos="0 0 0" axis="0 1 0" type="slide" range="0 0.044" actuatorfrcrange="-333 333"/>
                    <geom name="openarm_right_left_finger_visual" pos="0 -0.05 -0.673001" quat="1 0 0 0" type="mesh" contype="0" conaffinity="0" group="1" density="0" mesh="finger"/>
                    <geom name="openarm_right_left_finger_collision" pos="0 -0.05 -0.673001" quat="1 0 0 0" type="mesh" mesh="finger"/>
                  </body>
                </body>
              </body>
            </body>
          </body>
        </body>
      </body>
    </body>
  </worldbody>
</mujoco>
